Workbook

Sheet 4º RCC - RS

Sheet TUNAS - PR
A1: ESTAMOS OFERENCENDO DESCONTO DE 40,01% EM TODAS AS PASSSAGENS, USAR CALCULADORA A BAIXO PARA SIMPLIFICAR ORCAMENTO
C4: lance | E4: PRC AUMENTO | F4: 0.98664
B5: 0.401 | C5: =B5 -> 0.401 | E5: OBJETIVO | F5: 0.23
A7: CUSTO | B7: VLR REAL | C7: VLR DESCONTO | D7: VLR TOTAL | E7: VLT OBJET | F7: VLR ACRESCIMO | I7: CUSTO | J7: VLR REAL | K7: VLR DESCONTO | L7: VLR TOTAL | M7: VLT OBJET | N7: VLR ACRESCIMO
A8: 13300 | B8: =E8/(1-$B$5) -> 27310.518 | C8: =B8*$C$5 -> 10951.518 | D8: =B8-C8 -> 16359 | E8: =A8+(A8*$F$5) -> 16359 | F8: =B8-A8 -> 14010.518 | I8: 3250 | J8: =M8/(1-$B$5) -> 6673.6227 | K8: =J8*$C$5 -> 2676.1227 | L8: =J8-K8 -> 3997.5 | M8: =I8+(I8*$F$5) -> 3997.5 | N8: =J8-I8 -> 3423.6227
D9: LUCRO | L9: LUCRO
D10: =D8-A8 -> 3059 | L10: =L8-I8 -> 747.5
A11: quantidade pessoa | B11: 7 | F11: TOTAL P PESSOA
A12: =A8/B11 -> 1900 | F12: =D8/B11 -> 2337
A15: SOLICITACAO | B15: NOME | C15: DT NASCIMENTO | D15: CPF | E15: IDA | F15: DESTINO | G15: DATA IDA | H15: DATA VOLTA | I15: CUSTO | J15: VENDA VLR
A16: 45854 | B16: Douglas De Souza Guerreiro | C16: 31992 | D16: 057.372.039-80 | E16: IGU | F16: CWB | G16: 45912 | L16: =2989.11+A8 -> 16289.11
A17: 45854 | B17: Adriano Pereira Xavier | C17: 30505 | D17: 04520613930 | E17: IGU | F17: CWB | G17: 45912 | L17: =SUM(D8,L8) -> 20356.5
A18: 45912 | B18: Adriano Pereira Xavier | C18: =IFERROR(VLOOKUP(B18,'Página8'!A:B,2,0),"") -> 30505 | D18: =IFERROR(VLOOKUP(B18,'Página8'!A:C,3,0),"") -> 04520613930 | E18: CWB | F18: BSB | G18: 45986 | H18: 45989 | I18: 1256.33 | J18: 1487.18 | L18: =L17-L16 -> 4067.39
A19: 45912 | B19: Amailson Mateus dos Santos de jesus | C19: =IFERROR(VLOOKUP(B19,'Página8'!A:B,2,0),"") -> 36191 | D19: =IFERROR(VLOOKUP(B19,'Página8'!A:C,3,0),"") -> 11941708978 | E19: CWB | F19: BSB | G19: 45986 | H19: 45989 | I19: 1256.33 | J19: 1487.18
A20: 45912 | B20: Daniel Sikora | C20: =IFERROR(VLOOKUP(B20,'Página8'!A:B,2,0),"") -> 28963 | D20: =IFERROR(VLOOKUP(B20,'Página8'!A:C,3,0),"") -> 03586628935 | E20: CWB | F20: BSB | G20: 45986 | H20: 45989 | I20: 1256.33 | J20: 1487.18
A21: 45912 | B21: Denise de Fatima dos Santos | C21: =IFERROR(VLOOKUP(B21,'Página8'!A:B,2,0),"") -> 28507 | D21: =IFERROR(VLOOKUP(B21,'Página8'!A:C,3,0),"") -> 02498362975 | E21: CWB | F21: BSB | G21: 45986 | H21: 45989 | I21: 1256.33 | J21: 1487.18
A22: 45912 | B22: Douglas De Souza Guerreiro | C22: =IFERROR(VLOOKUP(B22,'Página8'!A:B,2,0),"") -> 31992 | D22: =IFERROR(VLOOKUP(B22,'Página8'!A:C,3,0),"") -> 057.372.039-80 | E22: CWB | F22: BSB | G22: 45986 | H22: 45989 | I22: 1256.33 | J22: 1487.18
A23: 45912 | B23: Eroildes de Jesus Burkner | C23: =IFERROR(VLOOKUP(B23,'Página8'!A:B,2,0),"") -> 25204 | D23: =IFERROR(VLOOKUP(B23,'Página8'!A:C,3,0),"") -> 766.831.259-53 | E23: CWB | F23: BSB | G23: 45986 | H23: 45989 | I23: 1256.33 | J23: 1487.18
A24: 45912 | B24: Mariza Gonçalves dos Reis Araujo | C24: =IFERROR(VLOOKUP(B24,'Página8'!A:B,2,0),"") -> 20991 | D24: =IFERROR(VLOOKUP(B24,'Página8'!A:C,3,0),"") -> 850.602.759-49 | E24: CWB | F24: BSB | G24: 45986 | H24: 45989 | I24: 1256.33 | J24: 1487.18
A25: 45912 | B25: Josilene Bonete de Faria | C25: =IFERROR(VLOOKUP(B25,'Página8'!A:B,2,0),"") -> 34243 | D25: =IFERROR(VLOOKUP(B25,'Página8'!A:C,3,0),"") -> 08093548963 | E25: CWB | F25: BSB | G25: 45986 | H25: 45988 | I25: 999.59 | J25: 1487.18
A26: 45912 | B26: Kauan Ariel De Souza Bomfim | C26: =IFERROR(VLOOKUP(B26,'Página8'!A:B,2,0),"") -> 37099 | D26: =IFERROR(VLOOKUP(B26,'Página8'!A:C,3,0),"") -> 10789785900 | E26: CWB | F26: BSB | G26: 45986 | H26: 45988 | I26: 999.59 | J26: 1487.18
A27: 45912 | B27: Miriam de Fátima Neres | C27: =IFERROR(VLOOKUP(B27,'Página8'!A:B,2,0),"") -> 31126 | D27: =IFERROR(VLOOKUP(B27,'Página8'!A:C,3,0),"") -> 07877179910 | E27: CWB | F27: BSB | G27: 45986 | H27: 45988 | I27: 999.59 | J27: 1487.18
A28: 45916 | B28: Jair de Oliveira Pereira | C28: =IFERROR(VLOOKUP(B28,'Página8'!A:B,2,0),"") -> 26914 | D28: =IFERROR(VLOOKUP(B28,'Página8'!A:C,3,0),"") -> 93884710915 | E28: CWB | F28: BSB | G28: 45986 | H28: 45989 | I28: 1256.33 | J28: 1487.18
C29: =IFERROR(VLOOKUP(B29,'Página8'!A:B,2,0),"") | D29: =IFERROR(VLOOKUP(B29,'Página8'!A:C,3,0),"") | I29: =SUM(I16:I28) -> 13049.41 | J29: =SUM(J16:J28) -> 16358.98 | K29: =J29-I29 -> 3309.57
C30: =IFERROR(VLOOKUP(B30,'Página8'!A:B,2,0),"") | D30: =IFERROR(VLOOKUP(B30,'Página8'!A:C,3,0),"")
C31: =IFERROR(VLOOKUP(B31,'Página8'!A:B,2,0),"") | D31: =IFERROR(VLOOKUP(B31,'Página8'!A:C,3,0),"")
C32: =IFERROR(VLOOKUP(B32,'Página8'!A:B,2,0),"") | D32: =IFERROR(VLOOKUP(B32,'Página8'!A:C,3,0),"")
C33: =IFERROR(VLOOKUP(B33,'Página8'!A:B,2,0),"") | D33: =IFERROR(VLOOKUP(B33,'Página8'!A:C,3,0),"")
C34: =IFERROR(VLOOKUP(B34,'Página8'!A:B,2,0),"") | D34: =IFERROR(VLOOKUP(B34,'Página8'!A:C,3,0),"")
C35: =IFERROR(VLOOKUP(B35,'Página8'!A:B,2,0),"") | D35: =IFERROR(VLOOKUP(B35,'Página8'!A:C,3,0),"")
C36: =IFERROR(VLOOKUP(B36,'Página8'!A:B,2,0),"") | D36: =IFERROR(VLOOKUP(B36,'Página8'!A:C,3,0),"")
A47: 25763200 Passagens,
A48: 100 idas e 100
A49: voltas200R$R$
A50: 25763200 Passagens,
A51: 100 idas e 100
A52: voltas200R$R$
A53: TOTAL:R$R$

Sheet 6º RCC - RS
A1: DATA SOLICITACAO | B1: DATA IDA | C1: DATA CHEGADA | D1: DE | E1: PARA | F1: HORARIO SAIDA | G1: HORARIO CHEGADA | H1: ASSENTO | I1: BILHETE | J1: CLASSE | K1: COLABORADOR | L1: CPF | M1: DT NASC | N1: VALOR | O1: CUSTO | P1: LUCRO | Q1: PERCENTIL | R1: Pago
A2: 45852 | B2: 45856 | C2: 45856 | D2: ALEGRETTE | E2: PORTO ALEGRE | F2: 0.10416667 | G2: 0.47916667 | H2: 9 | I2: 10065308799462 | J2: LEITO | K2: LUIZ GUSTAVO GONÇALVES DA SILVA | L2: 216.767.587-98 | M2: 37484 | N2: 624.7 | O2: 479.91 | P2: =N2-O2 -> 144.79 | Q2: =P2/N2 -> 0.23177525
A3: 45852 | B3: 45856 | C3: 45856 | D3: ALEGRETTE | E3: PORTO ALEGRE | F3: 0.10416667 | G3: 0.47916667 | H3: 2 | I3: 10065308799392 | J3: LEITO | K3: LOHAN WELLINGTON ROGACIANO DA SILVA | L3: 184.390.037-81 | M3: 36664 | N3: 624.7 | O3: 479.91 | P3: =N3-O3 -> 144.79 | Q3: =P3/N3 -> 0.23177525
A4: 45852 | B4: 45856 | C4: 45856 | D4: ALEGRETTE | E4: PORTO ALEGRE | F4: 0.10416667 | G4: 0.47916667 | H4: 6 | I4: 10065308799453 | J4: LEITO | K4: JOSÉ CARLOS ALVES DE SANTA ROSA | L4: 711.275.044-01 | M4: 39152 | N4: 624.7 | O4: 479.91 | P4: =N4-O4 -> 144.79 | Q4: =P4/N4 -> 0.23177525
A5: 45852 | B5: 45856 | C5: 45857 | D5: PORTO ALEGRE | E5: SAO PAULO TIETE | F5: 0.54166667 | G5: 0.41666667 | H5: 50 | I5: 010285313128 | J5: LEITO-CAMA | K5: LUIZ GUSTAVO GONÇALVES DA SILVA | L5: 216.767.587-98 | M5: 37484 | N5: 1130.2 | O5: 1009.5 | P5: =N5-O5 -> 120.7 | Q5: =P5/N5 -> 0.10679526
A6: 45852 | B6: 45856 | C6: 45857 | D6: PORTO ALEGRE | E6: SAO PAULO TIETE | F6: 0.54166667 | G6: 0.41666667 | H6: 53 | I6: 010285313129 | J6: LEITO-CAMA | K6: LOHAN WELLINGTON ROGACIANO DA SILVA | L6: 184.390.037-81 | M6: 36664 | N6: 1130.2 | O6: 1009.5 | P6: =N6-O6 -> 120.7 | Q6: =P6/N6 -> 0.10679526
A7: 45852 | B7: 45856 | C7: 45857 | D7: PORTO ALEGRE | E7: SAO PAULO TIETE | F7: 0.54166667 | G7: 0.41666667 | H7: 52 | I7: 010285313130 | J7: LEITO-CAMA | K7: JOSÉ CARLOS ALVES DE SANTA ROSA | L7: 711.275.044-01 | M7: 39152 | N7: 1130.2 | O7: 1009.5 | P7: =N7-O7 -> 120.7 | Q7: =P7/N7 -> 0.10679526
A8: 45852 | B8: 45857 | C8: 45857 | D8: SAO PAULO TIETE | E8: TAUBATE | F8: 0.5 | G8: 0.58333333 | H8: 31 | I8: 010227540217 | J8: CONVENCIONAL | K8: LUIZ GUSTAVO GONÇALVES DA SILVA | L8: 216.767.587-98 | M8: 37484 | N8: 189.3 | O8: 76.02 | P8: =N8-O8 -> 113.28 | Q8: =P8/N8 -> 0.59841521
A9: 45852 | B9: 45857 | C9: 45857 | D9: SAO PAULO TIETE | E9: TAUBATE | F9: 0.5 | G9: 0.58333333 | H9: 32 | I9: 010227540216 | J9: CONVENCIONAL | K9: LOHAN WELLINGTON ROGACIANO DA SILVA | L9: 184.390.037-81 | M9: 36664 | N9: 189.3 | O9: 76.02 | P9: =N9-O9 -> 113.28 | Q9: =P9/N9 -> 0.59841521
A10: 45852 | B10: 45857 | C10: 45857 | D10: SAO PAULO TIETE | E10: TAUBATE | F10: 0.5 | G10: 0.58333333 | H10: 35 | I10: 010227540215 | J10: CONVENCIONAL | K10: JOSÉ CARLOS ALVES DE SANTA ROSA | L10: 711.275.044-01 | M10: 39152 | N10: 189.3 | O10: 76.02 | P10: =N10-O10 -> 113.28 | Q10: =P10/N10 -> 0.59841521
M11: TOTAL | N11: =SUM(N2:N10) -> 5832.6 | O11: =SUM(O2:O10) -> 4696.29 | P11: =N11-O11 -> 1136.31 | Q11: =P11/N11 -> 0.19482049
R12: Sim
K15: 6507.4
C16: DATA | D16: DE | E16: PARA | F16: VALOR | K16: =K15/4 -> 1626.85
C17: 45687 | D17: ALEGRETTE | E17: PORTO ALEGRE | F17: 624.7 | G17: =F17/SUM(F$17:F$20) -> 0.31817256 | H17: 517.62
C18: 45688 | D18: CAMPINAS | E18: TRES CORACOES | F18: 357 | G18: =F18/SUM(F$17:F$20) -> 0.18182744 | H18: 295.01
C19: 45694 | D19: TRES CORACOES | E19: CAMPINAS | F19: 357 | G19: =F19/SUM(F$17:F$20) -> 0.18182744 | H19: 295
C20: 45695 | D20: PORTO ALEGRE | E20: ALEGRETTE | F20: 624.7 | G20: =F20/SUM(F$17:F$20) -> 0.31817256 | H20: 517.62

Sheet 13º RCM - SP
A1: DATA SOLICITACAO | B1: DATA IDA | C1: DATA CHEGADA | D1: DE | E1: PARA | F1: HORARIO SAIDA | G1: HORARIO CHEGADA | H1: ASSENTO | I1: BILHETE | J1: CLASSE | K1: COLABORADOR | L1: CPF | M1: DT NASC | N1: VALOR | O1: CUSTO | P1: LUCRO | Q1: PERCENTIL | R1: pago
A2: 45852 | B2: 45858 | C2: 45858 | D2: PIRASSUNUNGA | E2: TIETE | F2: 0.34375 | G2: 0.46875 | H2: 23 | I2: 010008502928 | J2: CONVENCIONAL | K2: GABRIEL ALVES MOREIRA | L2: 146.734.667-56 | M2: 37757 | N2: 496.99 | O2: 386.4 | P2: =N2-O2 -> 110.59 | Q2: =P2/N2 -> 0.22251957
A3: 45852 | B3: 45858 | C3: 45858 | D3: PIRASSUNUNGA | E3: TIETE | F3: 0.34375 | G3: 0.46875 | H3: 20 | I3: 010008502932 | J3: CONVENCIONAL | K3: MATEUS DA SILVA VALERIO | L3: 176.791.447-45 | M3: 37515 | N3: 496.99 | O3: 386.4 | P3: =N3-O3 -> 110.59 | Q3: =P3/N3 -> 0.22251957
A4: 45852 | B4: 45858 | C4: 45858 | D4: PIRASSUNUNGA | E4: TIETE | F4: 0.34375 | G4: 0.46875 | H4: 14 | I4: 010008503000 | J4: CONVENCIONAL | K4: VICTOR HUGO BARROS DASINGER | L4: 172.512.107-70 | M4: 38102 | N4: 496.99 | O4: 386.4 | P4: =N4-O4 -> 110.59 | Q4: =P4/N4 -> 0.22251957
A5: 45852 | B5: 45858 | C5: 45858 | D5: PIRASSUNUNGA | E5: TIETE | F5: 0.34375 | G5: 0.46875 | H5: 10 | I5: 010008503001 | J5: CONVENCIONAL | K5: GABRIEL PAULO DA SILVA | L5: 164.408.617-43 | M5: 38270 | N5: 496.99 | O5: 386.4 | P5: =N5-O5 -> 110.59 | Q5: =P5/N5 -> 0.22251957
A6: 45852 | B6: 45858 | C6: 45858 | D6: PIRASSUNUNGA | E6: TIETE | F6: 0.34375 | G6: 0.46875 | H6: 15 | I6: 010008502929 | J6: CONVENCIONAL | K6: THEO CASINI ROCHA | L6: 192.455.347-31 | M6: 38523 | N6: 496.99 | O6: 386.4 | P6: =N6-O6 -> 110.59 | Q6: =P6/N6 -> 0.22251957
A7: 45852 | B7: 45858 | C7: 45858 | D7: PIRASSUNUNGA | E7: TIETE | F7: 0.34375 | G7: 0.46875 | H7: 19 | I7: 010008502935 | J7: CONVENCIONAL | K7: JUAN PABLO DE CARVALHO ROCHO | L7: 711.524.794-31 | M7: 37770 | N7: 496.99 | O7: 386.4 | P7: =N7-O7 -> 110.59 | Q7: =P7/N7 -> 0.22251957
A8: 45852 | B8: 45858 | C8: 45858 | D8: PIRASSUNUNGA | E8: TIETE | F8: 0.34375 | G8: 0.46875 | H8: 8 | I8: 010008502934 | J8: CONVENCIONAL | K8: BRUNO CORDEIRO NEVES | L8: 146.647.817-92 | M8: 37395 | N8: 496.99 | O8: 386.4 | P8: =N8-O8 -> 110.59 | Q8: =P8/N8 -> 0.22251957
A9: 45852 | B9: 45858 | C9: 45858 | D9: PIRASSUNUNGA | E9: TIETE | F9: 0.34375 | G9: 0.46875 | H9: 4 | I9: 010008502933 | J9: CONVENCIONAL | K9: RAFAEL CAETANO COSTA | L9: 162.084.366-80 | M9: 37474 | N9: 496.99 | O9: 386.4 | P9: =N9-O9 -> 110.59 | Q9: =P9/N9 -> 0.22251957
A10: 45852 | B10: 45858 | C10: 45858 | D10: PIRASSUNUNGA | E10: TIETE | F10: 0.34375 | G10: 0.46875 | H10: 9 | I10: 010008503002 | J10: CONVENCIONAL | K10: MATEUS PEREIRA SILVA | L10: 133.834.544-36 | M10: 38335 | N10: 496.99 | O10: 386.4 | P10: =N10-O10 -> 110.59 | Q10: =P10/N10 -> 0.22251957
A11: 45852 | B11: 45858 | C11: 45858 | D11: PIRASSUNUNGA | E11: TIETE | F11: 0.34375 | G11: 0.46875 | H11: 7 | I11: 010008502931 | J11: CONVENCIONAL | K11: CRISTOFER DA SILVA PEREIRA | L11: 135.374.767-01 | M11: 38096 | N11: 496.99 | O11: 386.4 | P11: =N11-O11 -> 110.59 | Q11: =P11/N11 -> 0.22251957
A12: 45852 | B12: 45858 | C12: 45858 | D12: PIRASSUNUNGA | E12: TIETE | F12: 0.34375 | G12: 0.46875 | H12: 5 | I12: 010008503003 | J12: CONVENCIONAL | K12: PEDRO LEONEL BASTOS | L12: 160.738.187-77 | M12: 38702 | N12: 496.99 | O12: 386.4 | P12: =N12-O12 -> 110.59 | Q12: =P12/N12 -> 0.22251957
A13: 45852 | B13: 45858 | C13: 45858 | D13: TIETE | E13: TAUBATE | F13: 0.54166667 | G13: 0.64583333 | H13: 15 | I13: 010227542552 | J13: CONVENCIONAL | K13: GABRIEL ALVES MOREIRA | L13: 146.734.667-56 | M13: 37757
A14: 45852 | B14: 45858 | C14: 45858 | D14: TIETE | E14: TAUBATE | F14: 0.54166667 | G14: 0.64583333 | H14: 19 | I14: 010227542559 | J14: CONVENCIONAL | K14: MATEUS DA SILVA VALERIO | L14: 176.791.447-45 | M14: 37515
A15: 45852 | B15: 45858 | C15: 45858 | D15: TIETE | E15: TAUBATE | F15: 0.54166667 | G15: 0.64583333 | H15: 23 | I15: 010227542550 | J15: CONVENCIONAL | K15: VICTOR HUGO BARROS DASINGER | L15: 172.512.107-70 | M15: 38102
A16: 45852 | B16: 45858 | C16: 45858 | D16: TIETE | E16: TAUBATE | F16: 0.54166667 | G16: 0.64583333 | H16: 16 | I16: 010227542558 | J16: CONVENCIONAL | K16: GABRIEL PAULO DA SILVA | L16: 164.408.617-43 | M16: 38270
A17: 45852 | B17: 45858 | C17: 45858 | D17: TIETE | E17: TAUBATE | F17: 0.54166667 | G17: 0.64583333 | H17: 12 | I17: 010227542554 | J17: CONVENCIONAL | K17: THEO CASINI ROCHA | L17: 192.455.347-31 | M17: 38523
A18: 45852 | B18: 45858 | C18: 45858 | D18: TIETE | E18: TAUBATE | F18: 0.54166667 | G18: 0.64583333 | H18: 27 | I18: 010227542557 | J18: CONVENCIONAL | K18: JUAN PABLO DE CARVALHO ROCHO | L18: 711.524.794-31 | M18: 37770
A19: 45852 | B19: 45858 | C19: 45858 | D19: TIETE | E19: TAUBATE | F19: 0.54166667 | G19: 0.64583333 | H19: 20 | I19: 010227542560 | J19: CONVENCIONAL | K19: BRUNO CORDEIRO NEVES | L19: 146.647.817-92 | M19: 37395
A20: 45852 | B20: 45858 | C20: 45858 | D20: TIETE | E20: TAUBATE | F20: 0.54166667 | G20: 0.64583333 | H20: 24 | I20: 010227542553 | J20: CONVENCIONAL | K20: RAFAEL CAETANO COSTA | L20: 162.084.366-80 | M20: 37474
A21: 45852 | B21: 45858 | C21: 45858 | D21: TIETE | E21: TAUBATE | F21: 0.54166667 | G21: 0.64583333 | H21: 28 | I21: 010227542556 | J21: CONVENCIONAL | K21: MATEUS PEREIRA SILVA | L21: 133.834.544-36 | M21: 38335
A22: 45852 | B22: 45858 | C22: 45858 | D22: TIETE | E22: TAUBATE | F22: 0.54166667 | G22: 0.64583333 | H22: 31 | I22: 010227542551 | J22: CONVENCIONAL | K22: CRISTOFER DA SILVA PEREIRA | L22: 135.374.767-01 | M22: 38096
A23: 45852 | B23: 45858 | C23: 45858 | D23: TIETE | E23: TAUBATE | F23: 0.54166667 | G23: 0.64583333 | H23: 11 | I23: 010227542555 | J23: CONVENCIONAL | K23: PEDRO LEONEL BASTOS | L23: 160.738.187-77 | M23: 38702
A24: 45852 | B24: 45863 | C24: 45863 | D24: TAUBATE | E24: TIETE | F24: 0.54166667 | G24: 0.63888889 | H24: 3 | I24: 010227542565 | N24: =SUM(N2:N23) -> 5466.89 | R24: Ok
D25: - | E25: -
D26: - | E26: -
D27: - | E27: -

Sheet Página8
A1: NOME | B1: DATA NASC | C1: CPF
A2: =IFERROR(__xludf.DUMMYFUNCTION("IMPORTRANGE(""https://docs.google.com/spreadsheets/d/1aTvIrqNmmcWMKGcvTQK3YcRRqao-8Pnts2s5Mjh-jtA/edit?gid=0#gid=0"",""PASSAGEIROS!C2:e500"")"),"Gabriela Camargo Flose") -> Gabriela Camargo Flose | B2: =IFERROR(__xludf.DUMMYFUNCTION("""COMPUTED_VALUE"""),36638.0) -> 36638 | C2: =IFERROR(__xludf.DUMMYFUNCTION("""COMPUTED_VALUE"""),"51324394897") -> 51324394897
A3: =IFERROR(__xludf.DUMMYFUNCTION("""COMPUTED_VALUE"""),"Gabriel Venâncio Georgino") -> Gabriel Venâncio Georgino | B3: =IFERROR(__xludf.DUMMYFUNCTION("""COMPUTED_VALUE"""),35465.0) -> 35465 | C3: =IFERROR(__xludf.DUMMYFUNCTION("""COMPUTED_VALUE"""),"45662704830") -> 45662704830
A4: =IFERROR(__xludf.DUMMYFUNCTION("""COMPUTED_VALUE"""),"Graziela Ribeiro Caires") -> Graziela Ribeiro Caires | B4: =IFERROR(__xludf.DUMMYFUNCTION("""COMPUTED_VALUE"""),35674.0) -> 35674 | C4: =IFERROR(__xludf.DUMMYFUNCTION("""COMPUTED_VALUE"""),"47208941866") -> 47208941866
A5: =IFERROR(__xludf.DUMMYFUNCTION("""COMPUTED_VALUE"""),"Marcos Adriano Victor de Morais") -> Marcos Adriano Victor de Morais | B5: =IFERROR(__xludf.DUMMYFUNCTION("""COMPUTED_VALUE"""),34373.0) -> 34373 | C5: =IFERROR(__xludf.DUMMYFUNCTION("""COMPUTED_VALUE"""),"01739570480") -> 01739570480
A6: =IFERROR(__xludf.DUMMYFUNCTION("""COMPUTED_VALUE"""),"Paula Passos Ferreira ") -> Paula Passos Ferreira | B6: =IFERROR(__xludf.DUMMYFUNCTION("""COMPUTED_VALUE"""),33995.0) -> 33995 | C6: =IFERROR(__xludf.DUMMYFUNCTION("""COMPUTED_VALUE"""),"406.588.548-52 ") -> 406.588.548-52
A7: =IFERROR(__xludf.DUMMYFUNCTION("""COMPUTED_VALUE"""),"Danilo Gomes da Silva ") -> Danilo Gomes da Silva | B7: =IFERROR(__xludf.DUMMYFUNCTION("""COMPUTED_VALUE"""),33253.0) -> 33253 | C7: =IFERROR(__xludf.DUMMYFUNCTION("""COMPUTED_VALUE"""),3.9125065823E10) -> 39125065823
A8: =IFERROR(__xludf.DUMMYFUNCTION("""COMPUTED_VALUE"""),"Gustavo Alves de Oliveira ") -> Gustavo Alves de Oliveira | B8: =IFERROR(__xludf.DUMMYFUNCTION("""COMPUTED_VALUE"""),36777.0) -> 36777 | C8: =IFERROR(__xludf.DUMMYFUNCTION("""COMPUTED_VALUE"""),5.0470355816E10) -> 50470355816
A9: =IFERROR(__xludf.DUMMYFUNCTION("""COMPUTED_VALUE"""),"Jonathan Soares Souza") -> Jonathan Soares Souza | B9: =IFERROR(__xludf.DUMMYFUNCTION("""COMPUTED_VALUE"""),35435.0) -> 35435 | C9: =IFERROR(__xludf.DUMMYFUNCTION("""COMPUTED_VALUE"""),4.5142516826E10) -> 45142516826
A10: =IFERROR(__xludf.DUMMYFUNCTION("""COMPUTED_VALUE"""),"Thayná Almeida Calais") -> Thayná Almeida Calais | B10: =IFERROR(__xludf.DUMMYFUNCTION("""COMPUTED_VALUE"""),37893.0) -> 37893 | C10: =IFERROR(__xludf.DUMMYFUNCTION("""COMPUTED_VALUE"""),5.5535342831E10) -> 55535342831
A11: =IFERROR(__xludf.DUMMYFUNCTION("""COMPUTED_VALUE"""),"Fabiana Letícia Baldo ") -> Fabiana Letícia Baldo | B11: =IFERROR(__xludf.DUMMYFUNCTION("""COMPUTED_VALUE"""),32208.0) -> 32208 | C11: =IFERROR(__xludf.DUMMYFUNCTION("""COMPUTED_VALUE"""),"358.806.428-10 ") -> 358.806.428-10
A12: =IFERROR(__xludf.DUMMYFUNCTION("""COMPUTED_VALUE"""),"Nicole de Souza Okinokabu") -> Nicole de Souza Okinokabu | B12: =IFERROR(__xludf.DUMMYFUNCTION("""COMPUTED_VALUE"""),34742.0) -> 34742 | C12: =IFERROR(__xludf.DUMMYFUNCTION("""COMPUTED_VALUE"""),"06568145947") -> 06568145947
A13: =IFERROR(__xludf.DUMMYFUNCTION("""COMPUTED_VALUE"""),"Milaine Cezero Pimenta de Souza") -> Milaine Cezero Pimenta de Souza | B13: =IFERROR(__xludf.DUMMYFUNCTION("""COMPUTED_VALUE"""),26702.0) -> 26702 | C13: =IFERROR(__xludf.DUMMYFUNCTION("""COMPUTED_VALUE"""),1.6544944882E10) -> 16544944882
A14: =IFERROR(__xludf.DUMMYFUNCTION("""COMPUTED_VALUE"""),"Raphael Antonio Holanda Rodrigues") -> Raphael Antonio Holanda Rodrigues | B14: =IFERROR(__xludf.DUMMYFUNCTION("""COMPUTED_VALUE"""),32911.0) -> 32911 | C14: =IFERROR(__xludf.DUMMYFUNCTION("""COMPUTED_VALUE"""),"230.629.968-46") -> 230.629.968-46
A15: =IFERROR(__xludf.DUMMYFUNCTION("""COMPUTED_VALUE"""),"Katarina Holanda Okinokabu") -> Katarina Holanda Okinokabu | B15: =IFERROR(__xludf.DUMMYFUNCTION("""COMPUTED_VALUE"""),45364.0) -> 45364 | C15: =IFERROR(__xludf.DUMMYFUNCTION("""COMPUTED_VALUE"""),"025.144.678-61") -> 025.144.678-61
A16: =IFERROR(__xludf.DUMMYFUNCTION("""COMPUTED_VALUE"""),"Ada de Almeida Medeiros Porcino ") -> Ada de Almeida Medeiros Porcino | B16: =IFERROR(__xludf.DUMMYFUNCTION("""COMPUTED_VALUE"""),29590.0) -> 29590 | C16: =IFERROR(__xludf.DUMMYFUNCTION("""COMPUTED_VALUE"""),3.0602070899E10) -> 30602070899
A17: =IFERROR(__xludf.DUMMYFUNCTION("""COMPUTED_VALUE"""),"Gledson Costa Porcino ") -> Gledson Costa Porcino | B17: =IFERROR(__xludf.DUMMYFUNCTION("""COMPUTED_VALUE"""),28764.0) -> 28764 | C17: =IFERROR(__xludf.DUMMYFUNCTION("""COMPUTED_VALUE"""),2.65232898E10) -> 26523289800
A18: =IFERROR(__xludf.DUMMYFUNCTION("""COMPUTED_VALUE"""),"Tiago Kenji Komessu Coito ") -> Tiago Kenji Komessu Coito | B18: =IFERROR(__xludf.DUMMYFUNCTION("""COMPUTED_VALUE"""),33031.0) -> 33031 | C18: =IFERROR(__xludf.DUMMYFUNCTION("""COMPUTED_VALUE"""),3.9605583844E10) -> 39605583844
A19: =IFERROR(__xludf.DUMMYFUNCTION("""COMPUTED_VALUE"""),"Nathalia Lepore Lopes ") -> Nathalia Lepore Lopes | B19: =IFERROR(__xludf.DUMMYFUNCTION("""COMPUTED_VALUE"""),35956.0) -> 35956 | C19: =IFERROR(__xludf.DUMMYFUNCTION("""COMPUTED_VALUE"""),4.5374636863E10) -> 45374636863
A20: =IFERROR(__xludf.DUMMYFUNCTION("""COMPUTED_VALUE"""),"Gustavo Sanches Sanni") -> Gustavo Sanches Sanni | B20: =IFERROR(__xludf.DUMMYFUNCTION("""COMPUTED_VALUE"""),35390.0) -> 35390 | C20: =IFERROR(__xludf.DUMMYFUNCTION("""COMPUTED_VALUE"""),4.2510078836E10) -> 42510078836
A21: =IFERROR(__xludf.DUMMYFUNCTION("""COMPUTED_VALUE"""),"André Luiz de Araujo") -> André Luiz de Araujo | B21: =IFERROR(__xludf.DUMMYFUNCTION("""COMPUTED_VALUE"""),30010.0) -> 30010 | C21: =IFERROR(__xludf.DUMMYFUNCTION("""COMPUTED_VALUE"""),2.2299594841E10) -> 22299594841
A22: =IFERROR(__xludf.DUMMYFUNCTION("""COMPUTED_VALUE"""),"Jaqueline Stefani Ferreira da Rocha ") -> Jaqueline Stefani Ferreira da Rocha | B22: =IFERROR(__xludf.DUMMYFUNCTION("""COMPUTED_VALUE"""),37208.0) -> 37208 | C22: =IFERROR(__xludf.DUMMYFUNCTION("""COMPUTED_VALUE"""),5.0628546874E10) -> 50628546874
A23: =IFERROR(__xludf.DUMMYFUNCTION("""COMPUTED_VALUE"""),"Daniel Pereira Ramos") -> Daniel Pereira Ramos | B23: =IFERROR(__xludf.DUMMYFUNCTION("""COMPUTED_VALUE"""),36190.0) -> 36190 | C23: =IFERROR(__xludf.DUMMYFUNCTION("""COMPUTED_VALUE"""),4.0544523881E10) -> 40544523881
A24: =IFERROR(__xludf.DUMMYFUNCTION("""COMPUTED_VALUE"""),"João Pedro da Silva Pereira ") -> João Pedro da Silva Pereira | B24: =IFERROR(__xludf.DUMMYFUNCTION("""COMPUTED_VALUE"""),44454.0) -> 44454 | C24: =IFERROR(__xludf.DUMMYFUNCTION("""COMPUTED_VALUE"""),5.9672259867E10) -> 59672259867
A25: =IFERROR(__xludf.DUMMYFUNCTION("""COMPUTED_VALUE"""),"Esberto Silva Ramos") -> Esberto Silva Ramos | B25: =IFERROR(__xludf.DUMMYFUNCTION("""COMPUTED_VALUE"""),22783.0) -> 22783 | C25: =IFERROR(__xludf.DUMMYFUNCTION("""COMPUTED_VALUE"""),2.26665755E10) -> 22666575500
A26: =IFERROR(__xludf.DUMMYFUNCTION("""COMPUTED_VALUE"""),"Cristiniana Pereira Ramos ") -> Cristiniana Pereira Ramos | B26: =IFERROR(__xludf.DUMMYFUNCTION("""COMPUTED_VALUE"""),26164.0) -> 26164 | C26: =IFERROR(__xludf.DUMMYFUNCTION("""COMPUTED_VALUE"""),"717354885-34 ") -> 717354885-34
A27: =IFERROR(__xludf.DUMMYFUNCTION("""COMPUTED_VALUE"""),"Gabriela Alves dos Reis Schunck") -> Gabriela Alves dos Reis Schunck | B27: =IFERROR(__xludf.DUMMYFUNCTION("""COMPUTED_VALUE"""),35893.0) -> 35893 | C27: =IFERROR(__xludf.DUMMYFUNCTION("""COMPUTED_VALUE"""),4.8060147889E10) -> 48060147889
A28: =IFERROR(__xludf.DUMMYFUNCTION("""COMPUTED_VALUE"""),"Felipe Nunes Quinonez") -> Felipe Nunes Quinonez | B28: =IFERROR(__xludf.DUMMYFUNCTION("""COMPUTED_VALUE"""),37933.0) -> 37933 | C28: =IFERROR(__xludf.DUMMYFUNCTION("""COMPUTED_VALUE"""),4.4267735808E10) -> 44267735808
A29: =IFERROR(__xludf.DUMMYFUNCTION("""COMPUTED_VALUE"""),"Laura Tomáz de Aquino") -> Laura Tomáz de Aquino | B29: =IFERROR(__xludf.DUMMYFUNCTION("""COMPUTED_VALUE"""),36159.0) -> 36159 | C29: =IFERROR(__xludf.DUMMYFUNCTION("""COMPUTED_VALUE"""),4.6555802839E10) -> 46555802839
A30: =IFERROR(__xludf.DUMMYFUNCTION("""COMPUTED_VALUE"""),"Tamara Nascimento Soares Cavalcante ") -> Tamara Nascimento Soares Cavalcante | B30: =IFERROR(__xludf.DUMMYFUNCTION("""COMPUTED_VALUE"""),34654.0) -> 34654 | C30: =IFERROR(__xludf.DUMMYFUNCTION("""COMPUTED_VALUE"""),4.2296125832E10) -> 42296125832
A31: =IFERROR(__xludf.DUMMYFUNCTION("""COMPUTED_VALUE"""),"Carlos Henrique monte Cavalcante ") -> Carlos Henrique monte Cavalcante | B31: =IFERROR(__xludf.DUMMYFUNCTION("""COMPUTED_VALUE"""),34023.0) -> 34023 | C31: =IFERROR(__xludf.DUMMYFUNCTION("""COMPUTED_VALUE"""),"230.394.748-04") -> 230.394.748-04
A32: =IFERROR(__xludf.DUMMYFUNCTION("""COMPUTED_VALUE"""),"Rebeca Gomes Lemos") -> Rebeca Gomes Lemos | B32: =IFERROR(__xludf.DUMMYFUNCTION("""COMPUTED_VALUE"""),37242.0) -> 37242 | C32: =IFERROR(__xludf.DUMMYFUNCTION("""COMPUTED_VALUE"""),4.8929657826E10) -> 48929657826
A33: =IFERROR(__xludf.DUMMYFUNCTION("""COMPUTED_VALUE"""),"Karina rosa da silva ") -> Karina rosa da silva | B33: =IFERROR(__xludf.DUMMYFUNCTION("""COMPUTED_VALUE"""),30460.0) -> 30460 | C33: =IFERROR(__xludf.DUMMYFUNCTION("""COMPUTED_VALUE"""),"310.792.988-35 ") -> 310.792.988-35
A34: =IFERROR(__xludf.DUMMYFUNCTION("""COMPUTED_VALUE"""),"Suellen de Oliveira") -> Suellen de Oliveira | B34: =IFERROR(__xludf.DUMMYFUNCTION("""COMPUTED_VALUE"""),35011.0) -> 35011 | C34: =IFERROR(__xludf.DUMMYFUNCTION("""COMPUTED_VALUE"""),"420.282.348-65") -> 420.282.348-65
A35: =IFERROR(__xludf.DUMMYFUNCTION("""COMPUTED_VALUE"""),"JOELMA CLÁUDIA SILVEIRA RIBEIRO") -> JOELMA CLÁUDIA SILVEIRA RIBEIRO | B35: =IFERROR(__xludf.DUMMYFUNCTION("""COMPUTED_VALUE"""),27096.0) -> 27096 | C35: =IFERROR(__xludf.DUMMYFUNCTION("""COMPUTED_VALUE"""),"900801815-20") -> 900801815-20
A36: =IFERROR(__xludf.DUMMYFUNCTION("""COMPUTED_VALUE"""),"Thamires Barros da Silva ") -> Thamires Barros da Silva | B36: =IFERROR(__xludf.DUMMYFUNCTION("""COMPUTED_VALUE"""),36781.0) -> 36781 | C36: =IFERROR(__xludf.DUMMYFUNCTION("""COMPUTED_VALUE"""),4.8620195875E10) -> 48620195875
A37: =IFERROR(__xludf.DUMMYFUNCTION("""COMPUTED_VALUE"""),"Michelli Alves Santana ") -> Michelli Alves Santana | B37: =IFERROR(__xludf.DUMMYFUNCTION("""COMPUTED_VALUE"""),35036.0) -> 35036 | C37: =IFERROR(__xludf.DUMMYFUNCTION("""COMPUTED_VALUE"""),4.4186897883E10) -> 44186897883
A38: =IFERROR(__xludf.DUMMYFUNCTION("""COMPUTED_VALUE"""),"Vitor Henrique Boís Ramos ") -> Vitor Henrique Boís Ramos | B38: =IFERROR(__xludf.DUMMYFUNCTION("""COMPUTED_VALUE"""),35970.0) -> 35970 | C38: =IFERROR(__xludf.DUMMYFUNCTION("""COMPUTED_VALUE"""),4.8018459835E10) -> 48018459835
A39: =IFERROR(__xludf.DUMMYFUNCTION("""COMPUTED_VALUE"""),"Juliane Ramos Lima ") -> Juliane Ramos Lima | B39: =IFERROR(__xludf.DUMMYFUNCTION("""COMPUTED_VALUE"""),35067.0) -> 35067 | C39: =IFERROR(__xludf.DUMMYFUNCTION("""COMPUTED_VALUE"""),"434.934. 448-96") -> 434.934. 448-96
A40: =IFERROR(__xludf.DUMMYFUNCTION("""COMPUTED_VALUE"""),"Gabriela Alves dos Reis Schunck") -> Gabriela Alves dos Reis Schunck | B40: =IFERROR(__xludf.DUMMYFUNCTION("""COMPUTED_VALUE"""),35893.0) -> 35893 | C40: =IFERROR(__xludf.DUMMYFUNCTION("""COMPUTED_VALUE"""),4.8060147889E10) -> 48060147889
...

Sheet CAIS LINS - SP
A1: DT SOLICITAÇÃO | B1: REQ | C1: DATA | D1: DE | E1: PARA | F1: SERVIDOR | G1: TELEFONE | H1: CPF | I1: DT NASC | J1: VALOR | K1: Custo | L1: Lucro | M1: PREV PGTO | N1: ENVIADO FATURAMENTO
A2: 45805 | B2: 15 | C2: 45810 | D2: LINS - SP | E2: SÃO PAULO - SP | F2: Amanda Ferreira de Oliveira Santos | G2: (14) 99831-5756 | H2: 400.638.988-45 | I2: 34137 | J2: =N$2 -> 174 | K2: 111.07 | M2: VALOR | N2: 174
A3: 45805 | B3: 16 | C3: 45811 | D3: SÃO PAULO - SP | E3: LINS - SP | F3: Amanda Ferreira de Oliveira Santos | G3: (14) 99831-5756 | H3: 400.638.988-45 | I3: 34137 | J3: =N$2 -> 174
A4: 45805 | B4: 17 | C4: 45810 | D4: LINS - SP | E4: SÃO PAULO - SP | F4: Eliana Barbosa Candido Camargo | G4: (14) 99677-3727 | H4: 61.824.448-43 | I4: 23886 | J4: =N$2 -> 174 | K4: 111.07
A5: 45805 | B5: 18 | C5: 45811 | D5: SÃO PAULO - SP | E5: LINS - SP | F5: Eliana Barbosa Candido Camargo | G5: (14) 99677-3727 | H5: 61.824.448-43 | I5: 23886 | J5: =N$2 -> 174
A6: 45824 | B6: 19 | C6: 45823 | D6: LINS - SP | E6: SÃO PAULO - SP | F6: SIMONE APARECIDA GAMA | G6: (14) 35331669 | H6: 277.423.148-51 | I6: 29124 | J6: =N$2 -> 174
A7: 45824 | B7: 20 | C7: 45824 | D7: SÃO PAULO - SP | E7: LINS - SP | F7: SIMONE APARECIDA GAMA | H7: - | I7: - | J7: =N$2 -> 174
A8: 45826 | B8: 21 | C8: 45832 | D8: LINS - SP | E8: SÃO PAULO - SP | F8: Vanessa da Silva Nascimento | J8: =N$2 -> 174
A9: 45831 | B9: 22 | C9: 45838 | D9: SÃO PAULO - SP | E9: LINS - SP | F9: RERISON BEZERRA CAMPOS | J9: =N$2 -> 174
A10: 45831 | B10: 23 | C10: 45837 | D10: LINS - SP | E10: SÃO PAULO - SP | F10: AMANDA FERREIRA DE OLIVIERA SANTOS | J10: =N$2 -> 174
A11: 45831 | B11: 24 | C11: 45837 | D11: LINS - SP | E11: SÃO PAULO - SP | F11: RERISON BEZERRA CAMPOS | J11: =N$2 -> 174
A12: 45831 | B12: 25 | C12: 45838 | D12: SÃO PAULO - SP | E12: LINS - SP | F12: AMANDA FERREIRA DE OLIVIERA SANTOS | H12: - | I12: - | J12: =N$2 -> 174
F13: TOTAL | J13: =SUM(J2:J12) -> 1914
A15: JULHO
A16: 45834 | B16: 26 | C16: 45839 | D16: LINS - SP | E16: SÃO PAULO - SP | F16: Bruna Rodrigues Gimenes Andrade | G16: (14) 35331669 | H16: 381.669.518-35 | I16: 33330 | J16: =N$2 -> 174
A17: 45834 | B17: 29 | C17: 45839 | D17: LINS - SP | E17: SÃO PAULO - SP | F17: Leda Simone dos Santos Lelis | G17: (14) 35331669 | H17: 110.629.958-21 | I17: 25629 | J17: =N$2 -> 174
A18: 45834 | B18: 27 | C18: 45840 | D18: SÃO PAULO - SP | E18: LINS - SP | F18: Bruna Rodrigues Gimenes Andrade | G18: (14) 35331669 | H18: 381.669.518-35 | I18: 33330 | J18: =N$2 -> 174
A19: 45834 | B19: 28 | C19: 45840 | D19: SÃO PAULO - SP | E19: LINS - SP | F19: Leda Simone dos Santos Lelis | G19: (14) 35331669 | H19: 110.629.958-21 | I19: 25629 | J19: =N$2 -> 174
F20: TOTAL | J20: =SUM(J16:J19) -> 696
A21: AGOSTO
A22: 45863 | B22: 30 | C22: - | D22: CANCELADA | E22: - | F22: - | J22: 0
A23: 45863 | B23: 31 | C23: - | D23: CANCELADA | E23: - | F23: - | J23: 0
A24: 45877 | B24: 32 | C24: 45877 | D24: LINS - SP | E24: JAU - SP | F24: Fábio José dos Santos | J24: =N$2 -> 174
A25: 45889 | B25: 33 | C25: 45893 | D25: LINS - SP | E25: SÃO PAULO - SP | F25: Amanda Ferreira de Oliveira Santos | J25: =N$2 -> 174
A26: 45889 | B26: 35 | C26: 45893 | D26: LINS - SP | E26: SÃO PAULO - SP | F26: Rérison Bezerra Campos | J26: =N$2 -> 174
A27: 45889 | B27: 34 | C27: 45894 | D27: SÃO PAULO - SP | E27: LINS - SP | F27: Amanda Ferreira de Oliveira Santos | J27: =N$2 -> 174
A28: 45889 | B28: 36 | C28: 45894 | D28: SÃO PAULO - SP | E28: LINS - SP | F28: Rérison Bezerra Campos | J28: =N$2 -> 174
F29: TOTAL | J29: =SUM(J22:J28) -> 870 | M29: Pago
A30: SETEMBRO
A31: 45923 | B31: 37 | C31: 45931 | D31: LINS - SP | E31: SÃO PAULO - SP | F31: ALEXANDRE FARIA VENTURA | J31: 174 | K31: 183.6
A32: 45923 | B32: 38 | C32: 45932 | D32: SÃO PAULO - SP | E32: LINS - SP | F32: ALEXANDRE FARIA VENTURA | J32: 174 | K32: 183.6 | M32: Pago
J34: =J32+(J32*0.2) -> 208.8
A36: FEVEIRO/2026 | M36: edpermanente.cflins@gmail.com
A37: 46066 | B37: 1 | C37: 46071 | D37: LINS - SP | E37: SÃO PAULO - SP | F37: Marcos Roberto Garcia Sales | J37: 174 | M37: RH CAIS Clemente Ferreira <rh-caisl@saude.sp.gov.br>
A38: 46066 | B38: 2 | C38: 46072 | D38: SÃO PAULO - SP | E38: LINS - SP | F38: Marcos Roberto Garcia Sales | J38: 174
J40: =J38+J37 -> 348 | M40: PAGO | N40: SIM

Sheet TJ VITORIA - ES
A1: DT SOLICITACAO | B1: CHECK IN | C1: CHECK OUT | D1: Nº DIARIAS | E1: COLABORADOR | F1: REFEICOES | G1: VLR DIARIA | H1: PREV VLR REFEICAO | I1: VLR TOTAL | J1: CUSTO HOSPEDAGEM | K1: CUSTO REFEIÇÂO | L1: CUSTO TT | M1: LUCRO | N1: PREV PGTO | O1: ENVIADO FATURAMENTO
A2: 45803 | B2: 45824 | C2: 45827 | D2: =IF(C2-B2=0,"",C2-B2) -> 3 | E2: ALICE BIANCHINI | F2: 4 | G2: =D2*O$3 -> 1109.61 | H2: =F2*O$4 -> 759.92 | I2: =G2+H2 -> 1869.53 | M2: SIM | N2: ATA | O2: 2025
A3: 45803 | B3: 45825 | C3: 45827 | D3: =IF(C3-B3=0,"",C3-B3) -> 2 | E3: LUCIANA LOPES ROCHA | F3: 3 | G3: =D3*O$3 -> 739.74 | H3: =F3*O$4 -> 569.94 | I3: =G3+H3 -> 1309.68 | M3: SIM | N3: DIARIA | O3: 369.87
A4: 45833 | B4: 45837 | C4: 45839 | D4: =IF(C4-B4=0,"",C4-B4) -> 2 | E4: EDILSON VITORELLI DINIZ LIMA | F4: 2 | G4: =D4*O$3 -> 739.74 | H4: =F4*O$4 -> 379.96 | I4: =G4+H4 -> 1119.7 | M4: SIM | N4: REFEICAO | O4: 189.98
D5: =IF(C5-B5=0,"",C5-B5) | H5: TOTAL | I5: =SUM(I2:I4) -> 4298.91
A9: 45845 | B9: 45853 | C9: 45854 | D9: =IF(C9-B9=0,"",C9-B9) -> 1 | E9: Rafael Alves Esteves | F9: 3 | G9: =D9*O$3 -> 369.87 | H9: =F9*O$4 -> 569.94 | I9: =G9+H9 -> 939.81 | J9: 551 | M9: SIM
A10: AGOSTO
A12: 45833 | B12: 45890 | C12: 45891 | D12: =IF(C12-B12=0,"",C12-B12) -> 1 | E12: Fredie de Souza Didier Junior | F12: =D12*2 -> 2 | G12: =D12*O$3 -> 369.87 | H12: =F12*O$4 -> 379.96 | I12: =G12+H12 -> 749.83 | J12: 331 | M12: SIM
A13: 45860 | B13: 45875 | C13: 45877 | D13: =IF(C13-B13=0,"",C13-B13) -> 2 | E13: Emily Karle dos Santos Conceição | F13: 2 | G13: =D13*O$3 -> 739.74 | H13: =F13*O$4 -> 379.96 | I13: =G13+H13 -> 1119.7 | J13: 1500 | M13: SIM
A14: 45860 | B14: 45876 | C14: 45878 | D14: =IF(C14-B14=0,"",C14-B14) -> 2 | E14: Miguel Fontes | F14: 1 | G14: =D14*O$3 -> 739.74 | H14: =F14*O$4 -> 189.98 | I14: =G14+H14 -> 929.72 | M14: SIM
A15: 45860 | B15: 45889 | C15: 45891 | D15: =IF(C15-B15=0,"",C15-B15) -> 2 | E15: Jair dos Santos Junior | F15: 3 | G15: =D15*O$3 -> 739.74 | H15: =F15*O$4 -> 569.94 | I15: =G15+H15 -> 1309.68 | M15: SIM
A16: 45860 | B16: 45890 | C16: 45893 | D16: =IF(C16-B16=0,"",C16-B16) -> 3 | E16: Marcelo Elias Naschenweng | F16: 0 | G16: 1312.9 | I16: 1109.61 | J16: 1312.9 | K16: 1109.61 | M16: SIM
A17: 45860 | B17: 45895 | C17: 45897 | D17: =IF(C17-B17=0,"",C17-B17) -> 2 | E17: Franklin Brasil Santos | F17: 3 | G17: =D17*O$3 -> 739.74 | H17: =F17*O$4 -> 569.94 | I17: =G17+H17 -> 1309.68 | M17: SIM
A18: 45860 | B18: 45897 | C18: 45899 | D18: =IF(C18-B18=0,"",C18-B18) -> 2 | E18: Rafael Guimarães | F18: 2 | G18: =D18*O$3 -> 739.74 | H18: =F18*O$4 -> 379.96 | I18: =G18+H18 -> 1119.7 | M18: SIM
A19: 45860 | B19: 45897 | C19: 45899 | D19: =IF(C19-B19=0,"",C19-B19) -> 2 | E19: Danilo Cunha Diniz | F19: 3 | G19: =D19*O$3 -> 739.74 | H19: =F19*O$4 -> 569.94 | I19: =G19+H19 -> 1309.68 | M19: SIM
A20: 45860 | B20: 45897 | C20: 45899 | D20: =IF(C20-B20=0,"",C20-B20) -> 2 | E20: Gilmar Silva Batista | F20: 3 | G20: =D20*O$3 -> 739.74 | H20: =F20*O$4 -> 569.94 | I20: =G20+H20 -> 1309.68 | M20: SIM
A21: 45860 | B21: 45897 | C21: 45899 | D21: =IF(C21-B21=0,"",C21-B21) -> 2 | E21: Marcos Vinicius Barroso | F21: 2 | G21: =D21*O$3 -> 739.74 | H21: =F21*O$4 -> 379.96 | I21: =G21+H21 -> 1119.7 | M21: SIM
A22: 45870 | B22: 45883 | C22: 45884 | D22: =IF(C22-B22=0,"",C22-B22) -> 1 | E22: Mauro da Fonseca Ellovitch | F22: 1 | G22: =D22*O$3 -> 369.87 | H22: =F22*O$4 -> 189.98 | I22: =G22+H22 -> 559.85 | M22: SIM
A23: 45882 | B23: 45891 | C23: 45892 | D23: =IF(C23-B23=0,"",C23-B23) -> 1 | E23: Felipe Soares Damous | F23: 1 | G23: =D23*O$3 -> 369.87 | H23: =F23*O$4 -> 189.98 | I23: =G23+H23 -> 559.85 | M23: SIM
G24: =SUM(H12:H23) -> 4369.54 | H24: TOTAL | I24: =SUM(I12:I23) -> 12506.68
A26: SETEMBRO
A27: 45908 | B27: 45909 | C27: 45910 | D27: =IF(C27-B27=0,"",C27-B27) -> 1 | E27: Renato Cidades Batista | F27: =D27*2 -> 2 | G27: =D27*O$3 -> 369.87 | H27: =(F27/2)*O$4 -> 189.98 | I27: =G27+H27 -> 559.85 | J27: 534 | M27: SIM
A28: 45908 | B28: 45912 | C28: 45913 | D28: =IF(C28-B28=0,"",C28-B28) -> 1 | E28: Márcia Campos Eurico | F28: =D28*2 -> 2 | G28: =D28*O$3 -> 369.87 | H28: =(F28/2)*O$4 -> 189.98 | I28: =G28+H28 -> 559.85 | J28: 399 | M28: SIM
A29: 45908 | B29: 45915 | C29: 45916 | D29: =IF(C29-B29=0,"",C29-B29) -> 1 | E29: Flávia Marciano Monteiro | F29: =D29*2 -> 2 | G29: =D29*O$3 -> 369.87 | H29: =(F29/2)*O$4 -> 189.98 | I29: =G29+H29 -> 559.85 | J29: 399 | M29: SIM
A30: 45922 | B30: 45952 | C30: 45954 | D30: =IF(C30-B30=0,"",C30-B30) -> 2 | E30: Paulo Rogério Bonini | F30: =D30*2 -> 4 | G30: =D30*O$3 -> 739.74 | H30: =F30*O$4 -> 759.92 | I30: =G30+H30 -> 1499.66 | J30: 694.55 | M30: SIM
A31: 45922 | B31: 45959 | C31: 45961 | D31: =IF(C31-B31=0,"",C31-B31) -> 2 | E31: Sebastião Luz Brito | F31: =D31*2 -> 4 | G31: =D31*O$3 -> 739.74 | H31: =F31*O$4 -> 759.92 | I31: =G31+H31 -> 1499.66 | J31: 694.55 | M31: SIM
A32: 45922 | B32: 45960 | C32: 45961 | D32: =IF(C32-B32=0,"",C32-B32) -> 1 | E32: Nelson Nery Junior | F32: =D32*2 -> 2 | G32: =D32*O$3 -> 369.87 | H32: =F32*O$4 -> 379.96 | I32: =G32+H32 -> 749.83 | J32: 378.97 | M32: SIM
D33: =IF(C33-B33=0,"",C33-B33) | G33: =D33*O$3 -> 0
A35: OUTUBRO
B36: 45945 | C36: 45948 | D36: =IF(C36-B36=0,"",C36-B36) -> 3 | E36: Fabrício Castagna Lunardi | F36: =D36*2 -> 6 | G36: =D36*O$3 -> 1109.61 | H36: =F36*O$4 -> 1139.88 | I36: =G36+H36 -> 2249.49
A38: NOVEMBRO
A40: 45968 | B40: 45974 | C40: 45976 | D40: =IF(C40-B40=0,"",C40-B40) -> 2 | E40: Beclaute Oliveira Silva | F40: 4 | G40: =D40*O$3 -> 739.74 | H40: =F40*O$4 -> 759.92 | I40: =G40+H40 -> 1499.66 | M40: SIM
A41: 45968 | B41: 45974 | C41: 45976 | D41: =IF(C41-B41=0,"",C41-B41) -> 2 | E41: Edilson Santana Gonçalves Filho | F41: =D41*2 -> 4 | G41: =D41*O$3 -> 739.74 | H41: =F41*O$4 -> 759.92 | I41: =G41+H41 -> 1499.66 | M41: SIM
A42: 45965 | B42: 45979 | C42: 45981 | D42: =IF(C42-B42=0,"",C42-B42) -> 2 | E42: José Rogério Cruz e Tucci | F42: =D42*2 -> 4 | G42: =D42*O$3 -> 739.74 | H42: =F42*O$4 -> 759.92 | I42: =G42+H42 -> 1499.66 | M42: SIM
A43: 45965 | B43: 45979 | C43: 45981 | D43: 1 | E43: Sérgio Luiz Kukina | F43: 0 | G43: =D43*O$3 -> 369.87 | H43: NO SHOW | I43: 369.87 | M43: SIM
A44: 45965 | B44: 45974 | C44: 45975 | D44: =IF(C44-B44=0,"",C44-B44) -> 1 | E44: Ana Paula Mota da Costa e Silva | F44: 2 | G44: =D44*O$3 -> 369.87 | H44: =F44*O$4 -> 379.96 | I44: =G44+H44 -> 749.83 | M44: SIM
H46: TOTAL | I46: =SUM(I40:I45) -> 5618.68
A47: DEZEMBRO
A48: 45988 | B48: 45995 | C48: 45997 | D48: =IF(C48-B48=0,"",C48-B48) -> 2 | E48: Ana Claudia Brandão de Barros Correia | F48: 2 | G48: =D48*O$3 -> 739.74 | H48: =F48*O$4 -> 379.96 | I48: =G48+H48 -> 1119.7 | M48: SIM
A49: 45965 | B49: 45994 | C49: 45998 | D49: =IF(C49-B49=0,"",C49-B49) -> 4 | E49: Eduardo Alvares de Carvalho | F49: 4 | G49: =D49*O$3 -> 1479.48 | H49: =F49*O$4 -> 759.92 | I49: =G49+H49 -> 2239.4 | M49: SIM
...

Sheet COREN -MA
A1: DATA SOLICITACAO | B1: MODELO DE VEICULO | C1: PLACA | D1: SAIDA | E1: DATA | F1: COLABORADOR | G1: CPF | H1: DT NASCIMENTO | I1: VALOR | J1: CUSTO | K1: LUCRO | L1: PREV PGTO | M1: ENVIADO FATURAMENTO
A2: 45818 | B2: FRONTIER | C2: NUJ 9C55 | D2: PONTA DA ESPERA | E2: 45824 | F2: LOUREDIR CANTANHEDE | G2: 02919330330 | H2: 31721 | I2: =IF(C2<>"-",O$3,O$2) -> 481.76 | J2: 143 | K2: =I2-J2 -> 338.76 | N2: VLR PEDESTRE | O2: 32.12
A3: 45818 | B3: - | C3: - | D3: PONTA DA ESPERA | E3: 45824 | F3: Milene Barreto Brito | G3: 816.436.243-34 | H3: 28861 | I3: =IF(C3<>"-",O$3,O$2) -> 32.12 | J3: 11 | K3: =I3-J3 -> 21.12 | N3: VLR CARRO | O3: 481.76
A4: 45818 | B4: FRONTIER | C4: NUJ 9C55 | D4: CUJUPE | E4: 45828 | F4: LOUREDIR CANTANHEDE | G4: 02919330330 | H4: 31721 | I4: =IF(C4<>"-",O$3,O$2) -> 481.76 | J4: 143 | K4: =I4-J4 -> 338.76
A5: 45818 | B5: - | C5: - | D5: CUJUPE | E5: 45828 | F5: Milene Barreto Brito | G5: 816.436.243-34 | H5: 28861 | I5: =IF(C5<>"-",O$3,O$2) -> 32.12 | J5: 11 | K5: =I5-J5 -> 21.12
A6: 45825 | B6: FRONTIER | C6: NUJ 9C55 | D6: PONTA DA ESPERA | E6: 23/062025 | F6: BEATRIZ ALMEIDA | G6: 771.508.483-20 | H6: 28042 | I6: =IF(C6<>"-",O$3,O$2) -> 481.76 | J6: 143 | K6: =I6-J6 -> 338.76 | N6: emails
A7: 45825 | B7: - | C7: - | D7: PONTA DA ESPERA | E7: 23/062025 | F7: CASSIA CHAVES LOPES | G7: 017.528.303-69 | H7: 31594 | I7: =IF(C7<>"-",O$3,O$2) -> 32.12 | J7: 11 | K7: =I7-J7 -> 21.12 | N7: \ | O7: administracao@corenma.gov.br>, controladoria@corenma.gov.br <controladoria@corenma.gov.br>
A8: 45831 | B8: FRONTIER | C8: NUJ 9C55 | D8: PONTA DA ESPERA | E8: 45833 | F8: JONATHAN SILVA DOS SANTOS CAMPOS | G8: 056.907.183-60 | H8: 33666 | I8: =IF(C8<>"-",O$3,O$2) -> 481.76 | J8: 143 | K8: =I8-J8 -> 338.76 | O8: Gestão de Contratos
A9: 45831 | B9: - | C9: - | D9: PONTA DA ESPERA | E9: 45833 | F9: MARINA APOLONIO DE BARROS COSTA | G9: 001.818.263-13 | H9: 32675 | I9: =IF(C9<>"-",O$3,O$2) -> 32.12 | J9: 11 | K9: =I9-J9 -> 21.12 | O9: <gestaodecontratos@corenma.gov.br>
A10: 45831 | B10: - | C10: - | D10: PONTA DA ESPERA | E10: 45833 | F10: JAIRO MUNIZ DA SILVA | G10: 036.470.663-54 | H10: 33071 | I10: =IF(C10<>"-",O$3,O$2) -> 32.12 | J10: 11 | K10: =I10-J10 -> 21.12
A11: 45831 | B11: FRONTIER | C11: NUJ 9C55 | D11: CUJUPE | E11: 45835 | F11: JONATHAN SILVA DOS SANTOS CAMPOS | G11: 056.907.183-60 | H11: 33666 | I11: =IF(C11<>"-",O$3,O$2) -> 481.76 | J11: 143 | K11: =I11-J11 -> 338.76
A12: 45831 | B12: - | C12: - | D12: CUJUPE | E12: 45835 | F12: MARINA APOLONIO DE BARROS COSTA | G12: 001.818.263-13 | H12: 32675 | I12: =IF(C12<>"-",O$3,O$2) -> 32.12 | J12: 11 | K12: =I12-J12 -> 21.12
A13: 45831 | B13: - | C13: - | D13: CUJUPE | E13: 45835 | F13: JAIRO MUNIZ DA SILVA | G13: 036.470.663-54 | H13: 33071 | I13: =IF(C13<>"-",O$3,O$2) -> 32.12 | J13: 11 | K13: =I13-J13 -> 21.12
H14: TOTAL | I14: =SUM(I2:I13) -> 2633.64 | J14: =SUM(J2:J13) -> 792 | K14: =SUM(K2:K13) -> 1841.64 | L14: PAGO | M14: SIM
A15: JULHO
A16: 45840 | B16: - | C16: - | D16: CUJUPE | E16: 45854 | F16: LOUREDIR CANTANHEDE | G16: 02919330330 | H16: 31721 | I16: =IF(C16<>"-",O$3,O$2) -> 32.12 | J16: 11 | K16: =I16-J16 -> 21.12
A17: 45854 | B17: TIGGO 5X | C17: ROD 9C57 | D17: CUJUPE | E17: 45854 | F17: LOUREDIR CANTANHEDE | G17: 02919330330 | H17: 31721 | I17: =IF(C17<>"-",O$3,O$2) -> 481.76 | J17: 143 | K17: =I17-J17 -> 338.76
A18: 45854 | B18: TIGGO 5X | C18: ROD 9C57 | D18: PONTA DA ESPERA | E18: 45865 | F18: LOUREDIR CANTANHEDE | G18: 02919330330 | H18: 31721 | I18: =IF(C18<>"-",O$3,O$2) -> 481.76 | J18: 143 | K18: =I18-J18 -> 338.76
A19: 45840 | B19: - | C19: - | D19: PONTA DA ESPERA | E19: 45857 | F19: LOUREDIR CANTANHEDE | G19: 02919330330 | H19: 31721 | I19: =IF(C19<>"-",O$3,O$2) -> 32.12 | J19: 11 | K19: =I19-J19 -> 21.12
H21: TOTAL | I21: =SUM(I$16:I20) -> 1027.76 | J21: =SUM(J$16:J20) -> 308 | K21: =SUM(K$16:K20) -> 719.76 | L21: PAGO | M21: SIM
A22: AGOSTO
A23: 45876 | B23: TIGGO 5X | C23: ROD 9C57 | D23: CUJUPE | F23: LOUREDIR CANTANHEDE | G23: 02919330330 | H23: 31721 | I23: =IF(C23<>"-",O$3,O$2) -> 481.76 | J23: 143 | K23: =I23-J23 -> 338.76
A24: 45876 | B24: TIGGO 5X | C24: ROD 9C57 | D24: PONTA DA ESPERA | F24: LOUREDIR CANTANHEDE | G24: 02919330330 | H24: 31721 | I24: =IF(C24<>"-",O$3,O$2) -> 481.76 | J24: 143 | K24: =I24-J24 -> 338.76
H25: TOTAL | I25: =SUM(I$23:I24) -> 963.52 | J25: =SUM(J$23:J24) -> 286 | K25: =SUM(K$23:K24) -> 677.52 | L25: PAGO | M25: SIM | N25: OK
A26: SETEMBRO
A27: 45903 | B27: TIGGO 5X | C27: ROD 9C57 | D27: CUJUPE | E27: 45915 | F27: LOUREDIR CANTANHEDE | G27: 02919330330 | H27: 31721 | I27: =IF(C27<>"-",O$3,O$2) -> 481.76 | J27: 143 | K27: =I27-J27 -> 338.76
A28: 45903 | B28: TIGGO 5X | C28: ROD 9C57 | D28: PONTA DA ESPERA | E28: 45918 | F28: LOUREDIR CANTANHEDE | G28: 02919330330 | H28: 31721 | I28: =IF(C28<>"-",O$3,O$2) -> 481.76 | J28: 143 | K28: =I28-J28 -> 338.76
A29: 45903 | B29: FRONTIER | C29: NUJ 9C55 | D29: PONTA DA ESPERA | E29: 45922 | F29: LOUREDIR CANTANHEDE | G29: 02919330330 | H29: 31721 | I29: =IF(C29<>"-",O$3,O$2) -> 481.76 | J29: 143 | K29: =I29-J29 -> 338.76
A30: 45903 | B30: FRONTIER | C30: NUJ 9C55 | D30: PONTA DA ESPERA | E30: 45926 | F30: LOUREDIR CANTANHEDE | G30: 02919330330 | H30: 31721 | I30: =IF(C30<>"-",O$3,O$2) -> 481.76 | J30: 143 | K30: =I30-J30 -> 338.76
A31: 45903 | B31: - | C31: - | D31: PONTA DA ESPERA | E31: 45922 | F31: MILENE BARRETO BRITO | G31: 816.436.243-34 | H31: 28861 | I31: =IF(C31<>"-",O$3,O$2) -> 32.12 | J31: 11 | K31: =I31-J31 -> 21.12
A32: 45903 | B32: - | C32: - | D32: PONTA DA ESPERA | E32: 45926 | F32: MILENE BARRETO BRITO | G32: 816.436.243-34 | H32: 28861 | I32: =IF(C32<>"-",O$3,O$2) -> 32.12 | J32: 11 | K32: =I32-J32 -> 21.12
H34: TOTAL | I34: =SUM(I$27:I33) -> 1991.28 | J34: =SUM(J$27:J33) -> 594 | K34: =SUM(K$27:K33) -> 1397.28 | L34: PAGO | M34: SIM | N34: ok
A35: NOVEMBRO
A36: 45967 | B36: FRONTIER | C36: NUJ 9C55 | D36: PONTA DA ESPERA | E36: 45978 | F36: LOUREDIR CANTANHEDE | G36: 02919330330 | H36: 31721 | I36: =IF(C36<>"-",O$3,O$2) -> 481.76 | J36: 153 | K36: =I36-J36 -> 328.76
A37: 45967 | B37: - | C37: - | D37: PONTA DA ESPERA | E37: 45978 | F37: Milene Barreto Brito | G37: 816.436.243-34 | H37: 28861 | I37: =IF(C37<>"-",O$3,O$2) -> 32.12 | J37: 11 | K37: =I37-J37 -> 21.12
A38: 45967 | B38: FRONTIER | C38: NUJ 9C55 | D38: CUJUPE | E38: 45982 | F38: LOUREDIR CANTANHEDE | G38: 02919330330 | H38: 31721 | I38: =IF(C38<>"-",O$3,O$2) -> 481.76 | J38: 153 | K38: =I38-J38 -> 328.76
A39: 45967 | B39: - | C39: - | D39: CUJUPE | E39: 45982 | F39: Milene Barreto Brito | G39: 816.436.243-34 | H39: 28861 | I39: =IF(C39<>"-",O$3,O$2) -> 32.12 | J39: 11 | K39: =I39-J39 -> 21.12
H41: TOTAL | I41: =SUM(I$36:I40) -> 1027.76 | J41: =SUM(J$36:J40) -> 328 | K41: =SUM(K$36:K40) -> 699.76 | L41: PAGO | M41: SIM
A42: DEZEMBRO
A43: 45989 | B43: TIGGO 5X | C43: ROD 9C57 | D43: CUJUPE | E43: 46006 | F43: LOUREDIR CANTANHEDE | G43: 02919330330 | H43: 31721 | I43: =IF(C43<>"-",O$3,O$2) -> 481.76 | J43: 153 | K43: =I43-J43 -> 328.76
...
